Workbook

Sheet Calculator
A1: PROMO PLANNING CALCULATOR
A2: Configure cells in blue. Black cells are formulas — do not edit. Goal is set PER REP; team totals scale by Staff count.
A4: THE GOAL | G4: COMMISSIONS PLAN — per Lead Gen rep
A5: Monthly WRR target — PER REP / Lead Gen rep ($/wk by EOM) | B5: 1250 | G5: Bonus tiers (configurable). VLOOKUP keys off Min Attended.
A6: Average deal value ($/wk WRR per deal) | B6: 100 | G6: Min attended | H6: Tier | I6: Bonus ($) | J6: Payrise/yr ($)
A7: Working days per month | B7: 21 | G7: 0 | H7: Below threshold | I7: 0 | J7: 0
A8: Working days per week | B8: 5 | G8: 35 | H8: Tier 1 | I8: 800 | J8: 0
A9: Staff count (number of reps for this promo) | B9: 3 | G9: 40 | H9: Tier 2 | I9: 1000 | J9: 0
G10: 45 | H10: Tier 3 | I10: 1500 | J10: 0
A11: Deals required per month — PER REP | B11: =B5/B6 -> 12.5 | G11: 50 | H11: Tier 4 (sweet spot) | I11: 2000 | J11: 2500
A12: Deals required per month — TEAM (= per rep × staff) | B12: =B11*B9 -> 37.5 | G12: 60 | H12: Tier 5 (stretch) | I12: 2500 | J12: 2500
A14: FUNNEL CUT-THROUGHS — set Current to your assumption | G14: PROJECTED COMMISSION (this month)
A15: Stage | B15: Current | C15: Target | D15: Commit | E15: High | G15: Projected attended (per rep) | J15: =B43 -> 29.09088
A16: Pipeline → Deal close rate | B16: 0.51 | C16: 0.51 | D16: 0.51 | E16: 0.85 | G16: Current tier | J16: =INDEX($H$7:$H$12,MATCH(J15,$G$7:$G$12,1)) -> Below threshold
A17: Attended → Pipeline | B17: 0.65 | C17: 0.67 | D17: 0.7 | E17: 0.72 | G17: Bonus this month ($) | J17: =INDEX($I$7:$I$12,MATCH(J15,$G$7:$G$12,1)) -> 0
A18: Attended → Deal on Day | B18: 0.1 | C18: 0.05 | D18: 0.1 | E18: 0.2 | G18: Annual payrise unlocked ($/yr) | J18: =INDEX($J$7:$J$12,MATCH(J15,$G$7:$G$12,1)) -> 0
A19: Booking → Attended | B19: 0.2 | C19: 0.31 | D19: 0.4 | E19: 0.63 | G19: Monthly payrise equivalent ($/mo) | J19: =J18/12 -> 0
A20: Connected → Booking | B20: 0.12 | C20: 0.105 | D20: 0.12 | E20: 0.19
A21: Calls → Connected | B21: 0.52 | C21: 0.5 | D21: 0.52 | E21: 0.55 | G21: TOTAL THIS-MONTH VALUE (bonus + payrise/12) | J21: =J17+J19 -> 0
A22: Note: Attended outcomes split into Deal on Day, Pipeline, and Lost. Attended → Pipeline + Attended → Deal on Day should be ≤ 100%.
A24: REQUIRED ACTIVITY — PER REP (working backwards from each rep's monthly goal) | G24: DIALS/DAY TO UNLOCK EACH TIER (at current cut-throughs)
A25: Funnel stage | B25: Per rep / day | C25: Per rep / week | D25: Per rep / month | E25: TEAM / month | G25: Tier | H25: Min attended | I25: Dials / day | J25: Calls / month
A26: Total Deals | B26: =D26/$B$7 -> 0.5952381 | C26: =B26*$B$8 -> 2.9761905 | D26: =B11 -> 12.5 | E26: =D26*$B$9 -> 37.5 | G26: =H8 -> Tier 1 | H26: =G8 -> 35 | I26: =G8/$B$19/$B$20/$B$21/$B$7 -> 133.54701 | J26: =I26*$B$7 -> 2804.4872
A27: ↳ Deal on Day | B27: =D27/$B$7 -> 0.13794626 | C27: =B27*$B$8 -> 0.68973128 | D27: =D30*B18 -> 2.8968714 | E27: =D27*$B$9 -> 8.6906141 | G27: =H9 -> Tier 2 | H27: =G9 -> 40 | I27: =G9/$B$19/$B$20/$B$21/$B$7 -> 152.62515 | J27: =I27*$B$7 -> 3205.1282
A28: ↳ Pipeline deals | B28: =D28/$B$7 -> 0.45729184 | C28: =B28*$B$8 -> 2.2864592 | D28: =D29*B16 -> 9.6031286 | E28: =D28*$B$9 -> 28.809386 | G28: =H10 -> Tier 3 | H28: =G10 -> 45 | I28: =G10/$B$19/$B$20/$B$21/$B$7 -> 171.7033 | J28: =I28*$B$7 -> 3605.7692
A29: Pipeline (count) | B29: =D29/$B$7 -> 0.89665066 | C29: =B29*$B$8 -> 4.4832533 | D29: =D30*B17 -> 18.829664 | E29: =D29*$B$9 -> 56.488992 | G29: =H11 -> Tier 4 (sweet spot) | H29: =G11 -> 50 | I29: =G11/$B$19/$B$20/$B$21/$B$7 -> 190.78144 | J29: =I29*$B$7 -> 4006.4103
A30: Attended | B30: =D30/$B$7 -> 1.3794626 | C30: =B30*$B$8 -> 6.8973128 | D30: =B11/(B18+B17*B16) -> 28.968714 | E30: =D30*$B$9 -> 86.906141 | G30: =H12 -> Tier 5 (stretch) | H30: =G12 -> 60 | I30: =G12/$B$19/$B$20/$B$21/$B$7 -> 228.93773 | J30: =I30*$B$7 -> 4807.6923
A31: Bookings | B31: =D31/$B$7 -> 6.8973128 | C31: =B31*$B$8 -> 34.486564 | D31: =D30/B19 -> 144.84357 | E31: =D31*$B$9 -> 434.53071
A32: Connected calls | B32: =D32/$B$7 -> 57.477607 | C32: =B32*$B$8 -> 287.38803 | D32: =D31/B20 -> 1207.0297 | E32: =D32*$B$9 -> 3621.0892 | G32: How to read: this table back-calculates the per-rep dial volume needed to attend the tier threshold of meetings. Lower cut-throughs = MORE dials needed. Improve any of Booking→Attended (B19), Connected→Booking (B20), or Calls→Connected (B21) to drop the dials/day requirement. The Projected Commission section above pulls the per-rep Attended number from the Forward Projection — change Dialled calls per rep per day (B37) to see which tier each rep lands in.
A33: Calls (dialled) | B33: =D33/$B$7 -> 110.53386 | C33: =B33*$B$8 -> 552.6693 | D33: =D32/B21 -> 2321.211 | E33: =D33*$B$9 -> 6963.6331
A35: FORWARD PROJECTION (from per-rep dial volume)
A36: Set per-rep dial volume; team multiplier comes from Staff count above.
A37: Dialled calls per rep per day | B37: 111
A39: Funnel stage | B39: Per rep / mo | C39: Team / mo | D39: vs Per-rep Required
A40: Calls (dialled) | B40: =B37*B7 -> 2331 | C40: =B40*$B$9 -> 6993 | D40: =IFERROR(B40/D33,0) -> 1.0042172
A41: Connected calls | B41: =B40*B21 -> 1212.12 | C41: =B41*$B$9 -> 3636.36 | D41: =IFERROR(B41/D32,0) -> 1.0042172
A42: Bookings | B42: =B41*B20 -> 145.4544 | C42: =B42*$B$9 -> 436.3632 | D42: =IFERROR(B42/D31,0) -> 1.0042172
A43: Attended | B43: =B42*B19 -> 29.09088 | C43: =B43*$B$9 -> 87.27264 | D43: =IFERROR(B43/D30,0) -> 1.0042172
A44: Pipeline (count) | B44: =B43*B17 -> 18.909072 | C44: =B44*$B$9 -> 56.727216 | D44: =IFERROR(B44/D29,0) -> 1.0042172
A45: ↳ Pipeline deals | B45: =B44*B16 -> 9.6436267 | C45: =B45*$B$9 -> 28.93088 | D45: =IFERROR(B45/D28,0) -> 1.0042172
...

Sheet Reality Check
A1: REALITY CHECK — Rep actuals vs PER-REP requirement
A2: Rep "deals" = total (DoD + Pipeline combined). % Improvement compares each rep's pace to per-rep required deals from Calculator.
A4: Rep | B4: Days | C4: Dialled (raw) | D4: Connected | E4: Bookings | F4: Attended | G4: Total Deals | H4: Project. Deals | I4: % Improvement → Deals
A5: Cindy | B5: 17 | C5: 1950 | D5: 745 | E5: 91 | F5: 15 | G5: 1.5 | H5: =G5*Calculator!$B$7/B5 -> 1.8529412 | I5: =IFERROR((Calculator!$D$26-H5)/H5,0) -> 5.7460317
A6: Krishna | B6: 15 | C6: 1666 | D6: 685 | E6: 88 | F6: 14 | G6: 2.5 | H6: =G6*Calculator!$B$7/B6 -> 3.5 | I6: =IFERROR((Calculator!$D$26-H6)/H6,0) -> 2.5714286
A7: Sydney | B7: 17 | C7: 1531 | D7: 671 | E7: 69 | F7: 6 | G7: 1 | H7: =G7*Calculator!$B$7/B7 -> 1.2352941 | I7: =IFERROR((Calculator!$D$26-H7)/H7,0) -> 9.1190476
A8: Riley | B8: 18 | C8: 1546 | D8: 775 | E8: 93 | F8: 21 | G8: 0.5 | H8: =G8*Calculator!$B$7/B8 -> 0.58333333 | I8: =IFERROR((Calculator!$D$26-H8)/H8,0) -> 20.428571
A9: TEAM TOTAL | B9: =SUM(B5:B8) -> 67 | C9: =SUM(C5:C8) -> 6693 | D9: =SUM(D5:D8) -> 2876 | E9: =SUM(E5:E8) -> 341 | F9: =SUM(F5:F8) -> 56 | G9: =SUM(G5:G8) -> 5.5 | H9: =SUM(H5:H8) -> 7.1715686 | I9: =IFERROR((Calculator!$E$26-H9)/H9,0) -> 4.2289815
A12: STAGE-LEVEL TEAM TOTALS — projected to full month
A13: Funnel stage | B13: TEAM Required /mo | C13: Team projected /mo | D13: Gap (% lift needed)
A14: Calls (dialled) | B14: =Calculator!E33 -> 6963.6331 | C14: =SUMPRODUCT(C5:C8,Calculator!$B$7/B5:B8) -> 8436.1255 | D14: =IFERROR((B14-C14)/C14,0) -> -0.17454605
A15: Connected calls | B15: =Calculator!E32 -> 3621.0892 | C15: =SUMPRODUCT(D5:D8,Calculator!$B$7/B5:B8) -> 3612.3431 | D15: =IFERROR((B15-C15)/C15,0) -> 0.0024211671
A16: Bookings | B16: =Calculator!E31 -> 434.53071 | C16: =SUMPRODUCT(E5:E8,Calculator!$B$7/B5:B8) -> 429.34706 | D16: =IFERROR((B16-C16)/C16,0) -> 0.012073328
A17: Attended | B17: =Calculator!E30 -> 86.906141 | C17: =SUMPRODUCT(F5:F8,Calculator!$B$7/B5:B8) -> 70.041176 | D17: =IFERROR((B17-C17)/C17,0) -> 0.24078643
A18: Total deals | B18: =Calculator!E26 -> 37.5 | C18: =SUMPRODUCT(G5:G8,Calculator!$B$7/B5:B8) -> 7.1715686 | D18: =IFERROR((B18-C18)/C18,0) -> 4.2289815
A21: How to read: rep actuals are partial-month. Projected = actual × Working Days / Days Worked. Per-rep gap (col I) compares each rep's pace to their PER-REP share of the team goal. Team-level gap (row 9 col I) compares team total to the team-wide requirement. Stage-level table compares team-projected to TEAM-required at each funnel stage.

Sheet README
A1: PROMO PLANNING CALCULATOR — README
A3: What this is
A4: Excel mirror of /promo-planning. Now reframed as a PER-REP model: required activity is shown
A5: per individual rep, with a Team total column that scales by Staff count.
A6: • Calculator — main interactive model
A7: • Reality Check — rep actuals vs PER-REP requirement
A8: • README — this sheet
A10: How the model works
A11: 1. Set the TEAM monthly WRR target ($/wk) and average deal value.
A12: 2. Set Staff count — the model divides team goal by staff to get a per-rep target.
A13: 3. Configure the funnel cut-throughs in row 16–21.
A14: 4. Required Activity (rows 26–33) walks the per-rep target backwards through the funnel.
... A34: Live web version: training-portal-mauve.vercel.app/promo-planning
